Exception ignored in: <function _ProactorBasePipeTransport.__del__ at 0x000001BD577D9CF0>
Traceback (most recent call last):
  File "C:\Users\Alexandr\AppData\Local\Programs\Python\Python310\lib\asyncio\proactor_events.py", line 116, in __del__
  File "C:\Users\Alexandr\AppData\Local\Programs\Python\Python310\lib\asyncio\proactor_events.py", line 108, in close
  File "C:\Users\Alexandr\AppData\Local\Programs\Python\Python310\lib\asyncio\base_events.py", line 750, in call_soon
  File "C:\Users\Alexandr\AppData\Local\Programs\Python\Python310\lib\asyncio\base_events.py", line 515, in _check_closed
RuntimeError: Event loop is closed